Traceback (most recent call last):
  File "/home/runner/.cache/pypoetry/virtualenvs/deche-9hFjX_BT-py3.8/lib/python3.8/site-packages/jupyter_cache/executors/utils.py", line 51, in single_nb_execution
    executenb(
  File "/home/runner/.cache/pypoetry/virtualenvs/deche-9hFjX_BT-py3.8/lib/python3.8/site-packages/nbclient/client.py", line 1117, in execute
    return NotebookClient(nb=nb, resources=resources, km=km, **kwargs).execute()
  File "/home/runner/.cache/pypoetry/virtualenvs/deche-9hFjX_BT-py3.8/lib/python3.8/site-packages/nbclient/util.py", line 78, in wrapped
    return just_run(coro(*args, **kwargs))
  File "/home/runner/.cache/pypoetry/virtualenvs/deche-9hFjX_BT-py3.8/lib/python3.8/site-packages/nbclient/util.py", line 57, in just_run
    return loop.run_until_complete(coro)
  File "/opt/hostedtoolcache/Python/3.8.11/x64/lib/python3.8/asyncio/base_events.py", line 616, in run_until_complete
    return future.result()
  File "/home/runner/.cache/pypoetry/virtualenvs/deche-9hFjX_BT-py3.8/lib/python3.8/site-packages/nbclient/client.py", line 558, in async_execute
    await self.async_execute_cell(
  File "/home/runner/.cache/pypoetry/virtualenvs/deche-9hFjX_BT-py3.8/lib/python3.8/site-packages/nbclient/client.py", line 862, in async_execute_cell
    self._check_raise_for_error(cell, exec_reply)
  File "/home/runner/.cache/pypoetry/virtualenvs/deche-9hFjX_BT-py3.8/lib/python3.8/site-packages/nbclient/client.py", line 765, in _check_raise_for_error
    raise CellExecutionError.from_cell_and_msg(cell, exec_reply_content)
nbclient.exceptions.CellExecutionError: An error occurred while executing the following cell:
------------------
inc(1)
------------------

[0;31m---------------------------------------------------------------------------[0m
[0;31mAttributeError[0m                            Traceback (most recent call last)
[0;32m/tmp/ipykernel_1632/1816538619.py[0m in [0;36m<module>[0;34m[0m
[0;32m----> 1[0;31m [0minc[0m[0;34m([0m[0;36m1[0m[0;34m)[0m[0;34m[0m[0;34m[0m[0m
[0m
[0;32m~/work/deche/deche/deche/core.py[0m in [0;36mwrapper[0;34m(*args, **kwargs)[0m
[1;32m    260[0m             [0;32mif[0m [0mself[0m[0;34m.[0m[0mvalid[0m[0;34m([0m[0mpath[0m[0;34m=[0m[0;34mf"{path}/{key}"[0m[0;34m)[0m[0;34m:[0m[0;34m[0m[0;34m[0m[0m
[1;32m    261[0m                 [0;32mreturn[0m [0mself[0m[0;34m.[0m[0m_load[0m[0;34m([0m[0mfunc[0m[0;34m=[0m[0mfunc[0m[0;34m)[0m[0;34m([0m[0mkey[0m[0;34m=[0m[0mkey[0m[0;34m)[0m[0;34m[0m[0;34m[0m[0m
[0;32m--> 262[0;31m             [0;32melif[0m [0mself[0m[0;34m.[0m[0m_exists[0m[0;34m([0m[0mfunc[0m[0;34m=[0m[0mfunc[0m[0;34m,[0m [0mext[0m[0;34m=[0m[0mExtensions[0m[0;34m.[0m[0mexception[0m[0;34m)[0m[0;34m([0m[0mkey[0m[0;34m=[0m[0mkey[0m[0;34m)[0m[0;34m:[0m[0;34m[0m[0;34m[0m[0m
[0m[1;32m    263[0m                 [0;32mraise[0m [0mself[0m[0;34m.[0m[0m_load[0m[0;34m([0m[0mfunc[0m[0;34m=[0m[0mfunc[0m[0;34m,[0m [0mext[0m[0;34m=[0m[0mExtensions[0m[0;34m.[0m[0mexception[0m[0;34m)[0m[0;34m([0m[0mkey[0m[0;34m=[0m[0mkey[0m[0;34m)[0m[0;34m[0m[0;34m[0m[0m
[1;32m    264[0m             [0;32mtry[0m[0;34m:[0m[0;34m[0m[0;34m[0m[0m

[0;32m~/work/deche/deche/deche/core.py[0m in [0;36minner[0;34m(key, kwargs)[0m
[1;32m    198[0m             [0;32mif[0m [0mkey[0m [0;32mis[0m [0;32mNone[0m[0;34m:[0m[0;34m[0m[0;34m[0m[0m
[1;32m    199[0m                 [0mkey[0m [0;34m=[0m [0mfunc[0m[0;34m.[0m[0mtokenize[0m[0;34m([0m[0;34m**[0m[0mkwargs[0m[0;34m)[0m[0;34m[0m[0;34m[0m[0m
[0;32m--> 200[0;31m             [0;32mreturn[0m [0mself[0m[0;34m.[0m[0mfs[0m[0;34m.[0m[0mexists[0m[0;34m([0m[0mpath[0m[0;34m=[0m[0;34mf"{path}/{key}{ext or ''}"[0m[0;34m)[0m[0;34m[0m[0;34m[0m[0m
[0m[1;32m    201[0m [0;34m[0m[0m
[1;32m    202[0m         [0;32mreturn[0m [0minner[0m[0;34m[0m[0;34m[0m[0m

[0;31mAttributeError[0m: 'NoneType' object has no attribute 'exists'
AttributeError: 'NoneType' object has no attribute 'exists'

